Workbook

Sheet pivot table
A1: Create a pivot table to find the average Salary by each Category (group by Age groups if preferred).
E2: Use a pivot table to sum the Purchase_Count for each Satisfaction_Score value.
A3: age | B3: Average of Salary
A4: 18-22 | B4: 113670.91 | E4: satisfaction score | F4: Sum of Purchase_Count
A5: 23-27 | B5: 109207.64 | E5: 1.0618265 | F5: 26
A6: 28-32 | B6: 110173.91 | E6: 1.0972639 | F6: 6
A7: 33-37 | B7: 100473.25 | E7: 1.101403 | F7: 14
A8: 38-42 | B8: 95397.647 | E8: 1.122001 | F8: 8
A9: 43-47 | B9: 139902.2 | E9: 1.1437691 | F9: 24
A10: 48-52 | B10: 105434.5 | E10: 1.1493928 | F10: 36
A11: 53-57 | B11: 118253.64 | E11: 1.2067269 | F11: 29
A12: 58-62 | B12: 103652.62 | E12: 1.3138255 | F12: 33
A13: 63-67 | B13: 93498.5 | E13: 1.3413899 | F13: 25
A14: Grand Total | B14: 109321.51 | E14: 1.3759278 | F14: 3
E15: 1.388706 | F15: 25
E16: 1.5082421 | F16: 20
E17: 1.5603361 | F17: 30
E18: 1.6257482 | F18: 3
E19: 1.677971 | F19: 18
E20: 1.6931773 | F20: 7
E21: 1.7084427 | F21: 29
E22: 1.780972 | F22: 16
E23: 1.8632841 | F23: 25
E24: 1.9759586 | F24: 17
E25: 2.0009716 | F25: 17
E26: 2.083329 | F26: 33
... E104: 4.9602154 | F104: 31
E105: Grand Total | F105: 2447
B111: Build a pivot table to show the count of records per Visit_Frequency value.
B114: Count of Visit_Frequency
B115: 100
B121: Generate a pivot table that shows the minimum, maximum, and average Salary per Age group (e.g., 18-25, 26-35, etc.).
C125: age | D125: Min of Salary | E125: Max of Salary | F125: Average of Salary
C126: 18-22 | D126: 48419 | E126: 178371 | F126: 113670.91
C127: 23-27 | D127: 38986 | E127: 152659 | F127: 109207.64
C128: 28-32 | D128: 38545 | E128: 161330 | F128: 110173.91
C129: 33-37 | D129: 37666 | E129: 174213 | F129: 100473.25
C130: 38-42 | D130: 32392 | E130: 150657 | F130: 95397.647
C131: 43-47 | D131: 60222 | E131: 179736 | F131: 139902.2
C132: 48-52 | D132: 28748 | E132: 177906 | F132: 105434.5
...

Sheet Assignment_Data7 to 10
A1: Age | B1: Salary | C1: Purchase_Count | D1: Satisfaction_Score | E1: Visit_Frequency
A2: 56 | B2: 158767 | C2: 17 | D2: 1.9759586 | E2: 7
A3: 46 | B3: 149375 | C3: 38 | D3: 4.8920422 | E3: 5
A4: 32 | B4: 161330 | C4: 24 | D4: 2.5723909 | E4: 3
A5: 60 | B5: 64504 | C5: 5 | D5: 4.5681862 | E5: 12
A6: 25 | B6: 38986 | C6: 34 | D6: 3.5245545 | E6: 16
A7: 38 | B7: 86858 | C7: 6 | D7: 4.1792452 | E7: 19
A8: 56 | B8: 154312 | C8: 22 | D8: 3.0105484 | E8: 5
A9: 36 | B9: 37666 | C9: 11 | D9: 3.3076155 | E9: 14
A10: 40 | B10: 63660 | C10: 48 | D10: 2.9700708 | E10: 5
A11: 28 | B11: 159633 | C11: 16 | D11: 1.780972 | E11: 15
A12: 28 | B12: 51854 | C12: 33 | D12: 3.8898085 | E12: 17
A13: 41 | B13: 89505 | C13: 9 | D13: 2.1230894 | E13: 14
... A101: 61 | B101: 123506 | C101: 22 | D101: 4.8194611 | E101: 7
A102: =AVERAGE(A2:A101) -> 40.88 | B102: mean of age
A103: =MEDIAN(A2:A101) -> 41 | B103: median of age
A104: =MODE(A2:A101) -> 61 | B104: mode of age
B106: =_xlfn.STDEV.S(B2:B101) -> 44418.086 | C106: standard deviation of salary
D108: salary | E108: deviation (x-xbar) | F108: deviation (x-xbar)^2
D109: 158767 | E109: =D109-$B$106 -> 114348.91 | F109: =E109*E109 -> 1.3075674e+10
A110: =MIN(A2:A101) -> 18 | B110: min age | D110: 149375 | E110: =D110-$B$106 -> 104956.91 | F110: =E110*E110 -> 1.1015954e+10
A111: =MAX(A2:A101) -> 64 | B111: max age | D111: 161330 | E111: =D111-$B$106 -> 116911.91 | F111: =E111*E111 -> 1.3668396e+10
A112: =MIN(B2:B101) -> 27693 | B112: min salary | D112: 64504 | E112: =D112-$B$106 -> 20085.914 | F112: =E112*E112 -> 4.0344393e+08
A113: =MAX(B2:B101) -> 179736 | B113: max salary | D113: 38986 | E113: =D113-$B$106 -> -5432.0863 | F113: =E113*E113 -> 29507562
D114: 86858 | E114: =D114-$B$106 -> 42439.914 | F114: =E114*E114 -> 1.8011463e+09
D115: 154312 | E115: =D115-$B$106 -> 109893.91 | F115: =E115*E115 -> 1.2076672e+10
D116: 37666 | E116: =D116-$B$106 -> -6752.0863 | F116: =E116*E116 -> 45590670
D117: 63660 | E117: =D117-$B$106 -> 19241.914 | F117: =E117*E117 -> 3.7025124e+08
B118: skew of purchase | C118: =SKEW(C2:C101) -> 0.048663602 | D118: 159633 | E118: =D118-$B$106 -> 115214.91 | F118: =E118*E118 -> 1.3274476e+10
B119: kurtos of puchase count | C119: =KURT(C2:C101) -> -1.0551591 | D119: 51854 | E119: =D119-$B$106 -> 7435.9137 | F119: =E119*E119 -> 55292812
D120: 89505 | E120: =D120-$B$106 -> 45086.914 | F120: =E120*E120 -> 2.0328298e+09
D121: 129488 | E121: =D121-$B$106 -> 85069.914 | F121: =E121*E121 -> 7.2368902e+09
D122: 47662 | E122: =D122-$B$106 -> 3243.9137 | F122: =E122*E122 -> 10522976
B123: =SKEW(B2:B101) -> -0.25307872 | C123: skew of salary | D123: 33392 | E123: =D123-$B$106 -> -11026.086 | F123: =E123*E123 -> 1.2157458e+08
B124: =KURT(B2:B101) -> -1.2236235 | C124: kurt of salar | D124: 55535 | E124: =D124-$B$106 -> 11116.914 | F124: =E124*E124 -> 1.2358577e+08
D125: 138569 | E125: =D125-$B$106 -> 94150.914 | F125: =E125*E125 -> 8.8643945e+09
D126: 77256 | E126: =D126-$B$106 -> 32837.914 | F126: =E126*E126 -> 1.0783286e+09
D127: 114135 | E127: =D127-$B$106 -> 69716.914 | F127: =E127*E127 -> 4.8604481e+09
D128: 152478 | E128: =D128-$B$106 -> 108059.91 | F128: =E128*E128 -> 1.1676945e+10
D129: 60222 | E129: =D129-$B$106 -> 15803.914 | F129: =E129*E129 -> 2.4976369e+08
...

Sheet Summary statistics
A1: Column1 | C1: Column2 | E1: Column3 | G1: Column4 | I1: Column5
A3: Mean | B3: 40.88 | C3: Mean | D3: 109321.51 | E3: Mean | F3: 24.47 | G3: Mean | H3: 3.1356483 | I3: Mean | J3: 9.96 | N3: summary statistics
A4: Standard Error | B4: 1.399082 | C4: Standard Error | D4: 4441.8086 | E4: Standard Error | F4: 1.3994555 | G4: Standard Error | H4: 0.11712801 | I4: Standard Error | J4: 0.58204099
A5: Median | B5: 41 | C5: Median | D5: 118025.5 | E5: Median | F5: 24 | G5: Median | H5: 3.1837426 | I5: Median | J5: 10
A6: Mode | B6: 61 | C6: Mode | D6: #N/A | E6: Mode | F6: 48 | G6: Mode | H6: #N/A | I6: Mode | J6: 5
A7: Standard Deviation | B7: 13.99082 | C7: Standard Deviation | D7: 44418.086 | E7: Standard Deviation | F7: 13.994555 | G7: Standard Deviation | H7: 1.1712801 | I7: Standard Deviation | J7: 5.8204099
A8: Sample Variance | B8: 195.74303 | C8: Sample Variance | D8: 1.9729664e+09 | E8: Sample Variance | F8: 195.84758 | G8: Sample Variance | H8: 1.3718971 | I8: Sample Variance | J8: 33.877172
A9: Kurtosis | B9: -1.1665489 | C9: Kurtosis | D9: -1.2236235 | E9: Kurtosis | F9: -1.0551591 | G9: Kurtosis | H9: -1.1378841 | I9: Kurtosis | J9: -1.3664911
A10: Skewness | B10: 0.079166331 | C10: Skewness | D10: -0.25307872 | E10: Skewness | F10: 0.048663602 | G10: Skewness | H10: -0.16614507 | I10: Skewness | J10: 0.037765579
A11: Range | B11: 46 | C11: Range | D11: 152043 | E11: Range | F11: 48 | G11: Range | H11: 3.8983889 | I11: Range | J11: 18
A12: Minimum | B12: 18 | C12: Minimum | D12: 27693 | E12: Minimum | F12: 1 | G12: Minimum | H12: 1.0618265 | I12: Minimum | J12: 1
A13: Maximum | B13: 64 | C13: Maximum | D13: 179736 | E13: Maximum | F13: 49 | G13: Maximum | H13: 4.9602154 | I13: Maximum | J13: 19
A14: Sum | B14: 4088 | C14: Sum | D14: 10932151 | E14: Sum | F14: 2447 | G14: Sum | H14: 313.56483 | I14: Sum | J14: 996
A15: Count | B15: 100 | C15: Count | D15: 100 | E15: Count | F15: 100 | G15: Count | H15: 100 | I15: Count | J15: 100
A16: Column1 | C16: Column2 | E16: Column3 | G16: Column4 | I16: Column5
A18: Mean | B18: 1152.1896 | C18: Mean | D18: 85966.93 | E18: Mean | F18: 708.30019 | G18: Mean | H18: 2.1936006 | I18: Mean | J18: 304.91044
A19: Standard Error | B19: 1265.4813 | C19: Standard Error | D19: 90318.925 | E19: Standard Error | F19: 777.04961 | G19: Standard Error | H19: 2.2176478 | I19: Standard Error | J19: 335.30521
A20: Median | B20: 1378.7729 | C20: Median | D20: 94670.92 | E20: Median | F20: 845.79903 | G20: Median | H20: 2.2416949 | I20: Median | J20: 365.69999
A21: Mode | B21: 1492.0646 | C21: Mode | D21: #N/A | E21: Mode | F21: 914.54845 | G21: Mode | H21: #N/A | I21: Mode | J21: 396.09477
A22: Standard Deviation | B22: 1605.3562 | C22: Standard Deviation | D22: -2.7001301e+08 | E22: Standard Deviation | F22: 983.29787 | G22: Standard Deviation | H22: 159.30142 | I22: Standard Deviation | J22: 426.48955
A23: Sample Variance | B23: 1718.6478 | C23: Sample Variance | D23: -3.6811122e+08 | E23: Sample Variance | F23: 1052.0473 | G23: Sample Variance | H23: 181.72339 | I23: Sample Variance | J23: 456.88433
A24: Kurtosis | B24: 1831.9395 | C24: Kurtosis | D24: -4.6620944e+08 | E24: Kurtosis | F24: 1120.7967 | G24: Kurtosis | H24: 204.14535 | I24: Kurtosis | J24: 487.2791
A25: Skewness | B25: 1945.2311 | C25: Skewness | D25: -5.6430765e+08 | E25: Skewness | F25: 1189.5461 | G25: Skewness | H25: 226.56731 | I25: Skewness | J25: 517.67388
A26: Range | B26: 2058.5228 | C26: Range | D26: -6.6240587e+08 | E26: Range | F26: 1258.2956 | G26: Range | H26: 248.98928 | I26: Range | J26: 548.06866
A27: Minimum | B27: 2171.8144 | C27: Minimum | D27: -7.6050408e+08 | E27: Minimum | F27: 1327.045 | G27: Minimum | H27: 271.41124 | I27: Minimum | J27: 578.46344
A28: Maximum | B28: 2285.1061 | C28: Maximum | D28: -8.5860229e+08 | E28: Maximum | F28: 1395.7944 | G28: Maximum | H28: 293.83321 | I28: Maximum | J28: 608.85822
A29: Sum | B29: 2398.3977 | C29: Sum | D29: -9.5670051e+08 | E29: Sum | F29: 1464.5438 | G29: Sum | H29: 316.25517 | I29: Sum | J29: 639.25299
A30: Count | B30: 2511.6893 | C30: Count | D30: -1.0547987e+09 | E30: Count | F30: 1533.2932 | G30: Count | H30: 338.67713 | I30: Count | J30: 669.64777
A31: Column1 | C31: Column2 | E31: Column3 | G31: Column4 | I31: Column5
A33: Mean | B33: 2624.981 | C33: Mean | D33: 99022.915 | E33: Mean | F33: 1602.0427 | G33: Mean | H33: 2.2657421 | I33: Mean | J33: 700.04255
A34: Standard Error | B34: 2738.2726 | C34: Standard Error | D34: 103374.91 | E34: Standard Error | F34: 1670.7921 | G34: Standard Error | H34: 2.2897892 | I34: Standard Error | J34: 730.43733
A35: Median | B35: 2851.5643 | C35: Median | D35: 107726.9 | E35: Median | F35: 1739.5415 | G35: Median | H35: 2.3138364 | I35: Median | J35: 760.8321
A36: Mode | B36: 2964.8559 | C36: Mode | D36: #N/A | E36: Mode | F36: 1808.2909 | G36: Mode | H36: #N/A | I36: Mode | J36: 791.22688
A37: Standard Deviation | B37: 3078.1476 | C37: Standard Deviation | D37: -1.1528969e+09 | E37: Standard Deviation | F37: 1877.0404 | G37: Standard Deviation | H37: 361.0991 | I37: Standard Deviation | J37: 821.62166
A38: Sample Variance | B38: 3191.4392 | C38: Sample Variance | D38: -1.2509951e+09 | E38: Sample Variance | F38: 1945.7898 | G38: Sample Variance | H38: 383.52106 | I38: Sample Variance | J38: 852.01644
A39: Kurtosis | B39: 3304.7308 | C39: Kurtosis | D39: -1.3490934e+09 | E39: Kurtosis | F39: 2014.5392 | G39: Kurtosis | H39: 405.94303 | I39: Kurtosis | J39: 882.41122
A40: Skewness | B40: 3418.0225 | C40: Skewness | D40: -1.4471916e+09 | E40: Skewness | F40: 2083.2886 | G40: Skewness | H40: 428.36499 | I40: Skewness | J40: 912.80599
A41: Range | B41: 3531.3141 | C41: Range | D41: -1.5452898e+09 | E41: Range | F41: 2152.038 | G41: Range | H41: 450.78696 | I41: Range | J41: 943.20077
A42: Minimum | B42: 3644.6058 | C42: Minimum | D42: -1.643388e+09 | E42: Minimum | F42: 2220.7875 | G42: Minimum | H42: 473.20892 | I42: Minimum | J42: 973.59555
A43: Maximum | B43: 3757.8974 | C43: Maximum | D43: -1.7414862e+09 | E43: Maximum | F43: 2289.5369 | G43: Maximum | H43: 495.63088 | I43: Maximum | J43: 1003.9903
...

Sheet covariance 
B1: Column 1 | C1: Column 2 | D1: Column 3 | E1: Column 4 | F1: Column 5
A2: Column 1 | B2: =VARP('Assignment_Data7 to 10'!$A$2:$A$101) -> 193.7856
A3: Column 2 | B3: -10863.969 | C3: =VARP('Assignment_Data7 to 10'!$B$2:$B$101) -> 1.9532367e+09 | J3: covariance
A4: Column 3 | B4: 11.8764 | C4: -957.6997 | D4: =VARP('Assignment_Data7 to 10'!$C$2:$C$101) -> 193.8891
A5: Column 4 | B5: -1.7129647 | C5: -8462.2145 | D5: 0.4044766 | E5: =VARP('Assignment_Data7 to 10'!$D$2:$D$101) -> 1.3581782
A6: Column 5 | B6: -0.9948 | C6: -20024.91 | D6: -13.0512 | E6: 0.59528102 | F6: =VARP('Assignment_Data7 to 10'!$E$2:$E$101) -> 33.5384
B7: Column 1 | C7: Column 2 | D7: Column 3 | E7: Column 4 | F7: Column 5
A8: Column 6 | B8: =VARP('Assignment_Data7 to 10'!$A$2:$A$101) -> 193.7856
A9: Column 7 | B9: 5430.1331 | C9: =VARP('Assignment_Data7 to 10'!$B$2:$B$101) -> 1.9532367e+09
A10: Column 8 | B10: 8687.6664 | C10: -28882.151 | D10: =VARP('Assignment_Data7 to 10'!$C$2:$C$101) -> 193.8891
A11: Column 9 | B11: 11945.2 | C11: -38415.756 | D11: -26.506877 | E11: =VARP('Assignment_Data7 to 10'!$D$2:$D$101) -> 1.3581782
A12: Column 10 | B12: 15202.733 | C12: -47949.361 | D12: -39.962553 | E12: 0.59528102 | F12: =VARP('Assignment_Data7 to 10'!$E$2:$E$101) -> 33.5384
B13: Column 1 | C13: Column 2 | D13: Column 3 | E13: Column 4 | F13: Column 5
A14: Column 11 | B14: =VARP('Assignment_Data7 to 10'!$A$2:$A$101) -> 193.7856
A15: Column 12 | B15: 18460.266 | C15: =VARP('Assignment_Data7 to 10'!$B$2:$B$101) -> 1.9532367e+09
A16: Column 13 | B16: 21717.799 | C16: -57482.966 | D16: =VARP('Assignment_Data7 to 10'!$C$2:$C$101) -> 193.8891
A17: Column 14 | B17: 24975.333 | C17: -67016.571 | D17: -53.41823 | E17: =VARP('Assignment_Data7 to 10'!$D$2:$D$101) -> 1.3581782

Sheet Corelation
B1: Column 1 | C1: Column 2 | D1: Column 3 | E1: Column 4 | F1: Column 5
A2: Column 1 | B2: 1
A3: Column 2 | B3: -0.017658358 | C3: 1 | I3: Corelation
A4: Column 3 | B4: 0.061269928 | C4: -0.0015562351 | D4: 1
A5: Column 4 | B5: -0.10558672 | C5: -0.16429646 | D5: 0.024925182 | E5: 1
A6: Column 5 | B6: -0.012339679 | C6: -0.078238759 | D6: -0.16184623 | E6: 0.088200794 | F6: 1
B7: Column 1 | C7: Column 2 | D7: Column 3 | E7: Column 4 | F7: Column 5
A8: Column 6 | B8: -0.44864528
A9: Column 7 | B9: -0.65990605 | C9: -0.66038699
A10: Column 8 | B10: -0.87116682 | C10: -1.0001326 | D10: -0.87415324
A11: Column 9 | B11: -1.0824276 | C11: -1.3398783 | D11: -1.4550764 | E11: -0.82359841
A12: Column 10 | B12: -1.2936884 | C12: -1.6796239 | D12: -2.0359995 | E12: -1.7353976 | F12: 1
B13: Column 1 | C13: Column 2 | D13: Column 3 | E13: Column 4 | F13: Column 5
A14: Column 11 | B14: -1.5049491
A15: Column 12 | B15: -1.7162099 | C15: -2.0193696
A16: Column 13 | B16: -1.9274707 | C16: -2.3591152 | D16: -2.6169226
A17: Column 14 | B17: -2.1387315 | C17: -2.6988609 | D17: -3.1978457 | E17: -2.6471968
A18: Column 15 | B18: -2.3499922 | C18: -3.0386065 | D18: -3.7787688 | E18: -3.558996 | F18: 1
B19: Column 1 | C19: Column 2 | D19: Column 3 | E19: Column 4 | F19: Column 5
A20: Column 16 | B20: -2.561253
A21: Column 17 | B21: -2.7725138 | C21: -3.3783522
A22: Column 18 | B22: -2.9837745 | C22: -3.7180978 | D22: -4.3596919
A23: Column 19 | B23: -3.1950353 | C23: -4.0578435 | D23: -4.940615 | E23: -4.4707952
A24: Column 20 | B24: -3.4062961 | C24: -4.3975891 | D24: -5.5215381 | E24: -5.3825944 | F24: 1
B25: Column 1 | C25: Column 2 | D25: Column 3 | E25: Column 4 | F25: Column 5
A26: Column 21 | B26: -3.6175569
A27: Column 22 | B27: -3.8288176 | C27: -4.7373348
A28: Column 23 | B28: -4.0400784 | C28: -5.0770804 | D28: -6.1024613
A29: Column 24 | B29: -4.2513392 | C29: -5.4168261 | D29: -6.6833844 | E29: -6.2943937
A30: Column 25 | B30: -4.4625999 | C30: -5.7565717 | D30: -7.2643075 | E30: -7.2061929 | F30: 1
B31: Column 1 | C31: Column 2 | D31: Column 3 | E31: Column 4 | F31: Column 5
A32: Column 26 | B32: -4.6738607
A33: Column 27 | B33: -4.8851215 | C33: -6.0963174
A34: Column 28 | B34: -5.0963823 | C34: -6.436063 | D34: -7.8452306
A35: Column 29 | B35: -5.307643 | C35: -6.7758087 | D35: -8.4261537 | E35: -8.1179921
A36: Column 30 | B36: -5.5189038 | C36: -7.1155544 | D36: -9.0070768 | E36: -9.0297913 | F36: 1
B37: Column 1 | C37: Column 2 | D37: Column 3 | E37: Column 4 | F37: Column 5
